<?xml version="1.0" encoding="utf-8"?>
<!-- This URDF was automatically created by SolidWorks to URDF Exporter! Originally created by Stephen Brawner (brawner@gmail.com) 
     Commit Version: 1.6.0-4-g7f85cfe  Build Version: 1.6.7995.38578
     For more information, please see http://wiki.ros.org/sw_urdf_exporter -->
<robot
  name="samnple5">
  <link
    name="base_link">
    <inertial>
      <origin
        xyz="-0.0171776527088287 -0.065 0.000609083707823714"
        rpy="0 0 0" />
      <mass
        value="0.0435741374432618" />
      <inertia
        ixx="7.49906259217302E-06"
        ixy="1.42601771985693E-21"
        ixz="-9.49724979969621E-10"
        iyy="1.16663648857277E-05"
        iyz="4.98511806611715E-22"
        izz="1.63525589560706E-05" />
    </inertial>
    <visual>
      <origin
        xyz="0 0 0"
        rpy="0 0 0" />
      <geometry>
        <mesh
          filename="package://samnple5/meshes/base_link.STL" />
      </geometry>
      <material
        name="">
        <color
          rgba="0.792156862745098 0.819607843137255 0.933333333333333 1" />
      </material>
    </visual>
    <collision>
      <origin
        xyz="0 0 0"
        rpy="0 0 0" />
      <geometry>
        <mesh
          filename="package://samnple5/meshes/base_link.STL" />
      </geometry>
    </collision>
  </link>
  <link
    name="right_wheel">
    <inertial>
      <origin
        xyz="0 0 -0.005"
        rpy="0 0 0" />
      <mass
        value="0.012284" />
      <inertia
        ixx="1.3584E-06"
        ixy="1.3035E-38"
        ixz="1.7095E-23"
        iyy="1.3584E-06"
        iyz="1.0196E-53"
        izz="2.512E-06" />
    </inertial>
    <visual>
      <origin
        xyz="0 0 0"
        rpy="0 0 0" />
      <geometry>
        <mesh
          filename="package://samnple5/meshes/right_wheel.STL" />
      </geometry>
      <material
        name="">
        <color
          rgba="0.79216 0.81961 0.93333 1" />
      </material>
    </visual>
    <collision>
      <origin
        xyz="0 0 0"
        rpy="0 0 0" />
      <geometry>
        <mesh
          filename="package://samnple5/meshes/right_wheel.STL" />
      </geometry>
    </collision>
  </link>
  <joint
    name="right_wheel_joint"
    type="continuous">
    <origin
      xyz="-0.0053954 -0.045 0.00052896"
      rpy="1.5708 0 0" />
    <parent
      link="base_link" />
    <child
      link="right_wheel" />
    <axis
      xyz="0 0 1" />
  </joint>
  <link
    name="left_wheel">
    <inertial>
      <origin
        xyz="0 -1.7347E-18 0.005"
        rpy="0 0 0" />
      <mass
        value="0.012284" />
      <inertia
        ixx="1.3584E-06"
        ixy="4.8592E-42"
        ixz="1.7095E-23"
        iyy="1.3584E-06"
        iyz="-2.4831E-39"
        izz="2.512E-06" />
    </inertial>
    <visual>
      <origin
        xyz="0 0 0"
        rpy="0 0 0" />
      <geometry>
        <mesh
          filename="package://samnple5/meshes/left_wheel.STL" />
      </geometry>
      <material
        name="">
        <color
          rgba="0.79216 0.81961 0.93333 1" />
      </material>
    </visual>
    <collision>
      <origin
        xyz="0 0 0"
        rpy="0 0 0" />
      <geometry>
        <mesh
          filename="package://samnple5/meshes/left_wheel.STL" />
      </geometry>
    </collision>
  </link>
  <joint
    name="left_wheel_joint"
    type="continuous">
    <origin
      xyz="-0.0053954 -0.085 0.00052896"
      rpy="1.5708 0 0" />
    <parent
      link="base_link" />
    <child
      link="left_wheel" />
    <axis
      xyz="0 0 1" />
  </joint>
</robot>